Workbook

Sheet Dashboard
A1: DASHBOARD DE PRODUÇÃO INTELECTUAL
A2: Fonte: aba Matriz (projetos × 12 canais) e aba Periódicos. Todos os indicadores são fórmulas.
A4: Projetos cadastrados | C4: Saídas concluídas (canais) | E4: Links registrados | G4: Cobertura geral | I4: Média saídas/projeto | K4: Projetos multicanal (≥3)
A5: =COUNTIF(Matriz!$C$2:$C$60,"<>") -> 47 | C5: =SUM(Matriz!$AE$2:$AE$60) -> 111 | E5: =SUM(Matriz!$AF$2:$AF$60) -> 59 | G5: =IFERROR($C$5/($A$5*12),0) -> 0.19680851 | I5: =IFERROR($C$5/$A$5,0) -> 2.3617021 | K5: =COUNTIF(Matriz!$AE$2:$AE$60,">=3") -> 8
A7: Projetos com ≥1 saída | C7: Projetos sem saída | E7: Temas ativos | G7: Canais ativos | I7: Periódicos mapeados | K7: Periódicos fit ≥4
A8: =COUNTIF(Matriz!$AE$2:$AE$60,">=1") -> 47 | C8: =COUNTIF(Matriz!$AE$2:$AE$60,0) -> 0 | E8: =COUNTIF($C$12:$C$23,">0") -> 12 | G8: =COUNTIF($H$12:$H$23,">0") -> 6 | I8: =COUNTIF(Periódicos!$A$2:$A$168,"<>") -> 167 | K8: =COUNTIF(Periódicos!$I$2:$I$168,">=4") -> 113
A10: PRODUÇÃO POR TEMA | G10: PRODUÇÃO POR CANAL
A11: Tema | B11: Saídas concluídas | C11: Projetos | D11: Links | E11: Cobertura | G11: Canal | H11: Saídas concluídas | I11: Links | J11: Cobertura
A12: Álgebra | B12: =SUMIF(Matriz!$B$2:$B$60,$A12,Matriz!$AE$2:$AE$60) -> 4 | C12: =COUNTIFS(Matriz!$B$2:$B$60,$A12,Matriz!$C$2:$C$60,"<>") -> 2 | D12: =SUMIF(Matriz!$B$2:$B$60,$A12,Matriz!$AF$2:$AF$60) -> 2 | E12: =IFERROR($B12/($C12*12),0) -> 0.16666667 | G12: arXiv/SSRN | H12: =SUM(INDEX(Matriz!$F$2:$Q$60,0,MATCH($G12,Matriz!$F$1:$Q$1,0))) -> 8 | I12: =COUNTIF(INDEX(Matriz!$R$2:$AC$60,0,MATCH($G12&" (link)",Matriz!$R$1:$AC$1,0)),"http*") -> 8 | J12: =IFERROR($H12/$A$5,0) -> 0.17021277
A13: algebra | B13: =SUMIF(Matriz!$B$2:$B$60,$A13,Matriz!$AE$2:$AE$60) -> 2 | C13: =COUNTIFS(Matriz!$B$2:$B$60,$A13,Matriz!$C$2:$C$60,"<>") -> 1 | D13: =SUMIF(Matriz!$B$2:$B$60,$A13,Matriz!$AF$2:$AF$60) -> 1 | E13: =IFERROR($B13/($C13*12),0) -> 0.16666667 | G13: Journal | H13: =SUM(INDEX(Matriz!$F$2:$Q$60,0,MATCH($G13,Matriz!$F$1:$Q$1,0))) -> 8 | I13: =COUNTIF(INDEX(Matriz!$R$2:$AC$60,0,MATCH($G13&" (link)",Matriz!$R$1:$AC$1,0)),"http*") -> 8 | J13: =IFERROR($H13/$A$5,0) -> 0.17021277
A14: Análise de dados | B14: =SUMIF(Matriz!$B$2:$B$60,$A14,Matriz!$AE$2:$AE$60) -> 6 | C14: =COUNTIFS(Matriz!$B$2:$B$60,$A14,Matriz!$C$2:$C$60,"<>") -> 3 | D14: =SUMIF(Matriz!$B$2:$B$60,$A14,Matriz!$AF$2:$AF$60) -> 3 | E14: =IFERROR($B14/($C14*12),0) -> 0.16666667 | G14: Research Gate | H14: =SUM(INDEX(Matriz!$F$2:$Q$60,0,MATCH($G14,Matriz!$F$1:$Q$1,0))) -> 8 | I14: =COUNTIF(INDEX(Matriz!$R$2:$AC$60,0,MATCH($G14&" (link)",Matriz!$R$1:$AC$1,0)),"http*") -> 0 | J14: =IFERROR($H14/$A$5,0) -> 0.17021277
A15: Análise matemática | B15: =SUMIF(Matriz!$B$2:$B$60,$A15,Matriz!$AE$2:$AE$60) -> 16 | C15: =COUNTIFS(Matriz!$B$2:$B$60,$A15,Matriz!$C$2:$C$60,"<>") -> 8 | D15: =SUMIF(Matriz!$B$2:$B$60,$A15,Matriz!$AF$2:$AF$60) -> 8 | E15: =IFERROR($B15/($C15*12),0) -> 0.16666667 | G15: YouTube | H15: =SUM(INDEX(Matriz!$F$2:$Q$60,0,MATCH($G15,Matriz!$F$1:$Q$1,0))) -> 40 | I15: =COUNTIF(INDEX(Matriz!$R$2:$AC$60,0,MATCH($G15&" (link)",Matriz!$R$1:$AC$1,0)),"http*") -> 40 | J15: =IFERROR($H15/$A$5,0) -> 0.85106383
A16: Ciência de Dados e IA | B16: =SUMIF(Matriz!$B$2:$B$60,$A16,Matriz!$AE$2:$AE$60) -> 2 | C16: =COUNTIFS(Matriz!$B$2:$B$60,$A16,Matriz!$C$2:$C$60,"<>") -> 1 | D16: =SUMIF(Matriz!$B$2:$B$60,$A16,Matriz!$AF$2:$AF$60) -> 1 | E16: =IFERROR($B16/($C16*12),0) -> 0.16666667 | G16: TikTok | H16: =SUM(INDEX(Matriz!$F$2:$Q$60,0,MATCH($G16,Matriz!$F$1:$Q$1,0))) -> 40 | I16: =COUNTIF(INDEX(Matriz!$R$2:$AC$60,0,MATCH($G16&" (link)",Matriz!$R$1:$AC$1,0)),"http*") -> 2 | J16: =IFERROR($H16/$A$5,0) -> 0.85106383
A17: Estatística e Probabilidade | B17: =SUMIF(Matriz!$B$2:$B$60,$A17,Matriz!$AE$2:$AE$60) -> 2 | C17: =COUNTIFS(Matriz!$B$2:$B$60,$A17,Matriz!$C$2:$C$60,"<>") -> 1 | D17: =SUMIF(Matriz!$B$2:$B$60,$A17,Matriz!$AF$2:$AF$60) -> 1 | E17: =IFERROR($B17/($C17*12),0) -> 0.16666667 | G17: LinkedIn | H17: =SUM(INDEX(Matriz!$F$2:$Q$60,0,MATCH($G17,Matriz!$F$1:$Q$1,0))) -> 0 | I17: =COUNTIF(INDEX(Matriz!$R$2:$AC$60,0,MATCH($G17&" (link)",Matriz!$R$1:$AC$1,0)),"http*") -> 0 | J17: =IFERROR($H17/$A$5,0) -> 0
A18: Física Clássica | B18: =SUMIF(Matriz!$B$2:$B$60,$A18,Matriz!$AE$2:$AE$60) -> 26 | C18: =COUNTIFS(Matriz!$B$2:$B$60,$A18,Matriz!$C$2:$C$60,"<>") -> 10 | D18: =SUMIF(Matriz!$B$2:$B$60,$A18,Matriz!$AF$2:$AF$60) -> 15 | E18: =IFERROR($B18/($C18*12),0) -> 0.21666667 | G18: Newsletter LinkedIn | H18: =SUM(INDEX(Matriz!$F$2:$Q$60,0,MATCH($G18,Matriz!$F$1:$Q$1,0))) -> 0 | I18: =COUNTIF(INDEX(Matriz!$R$2:$AC$60,0,MATCH($G18&" (link)",Matriz!$R$1:$AC$1,0)),"http*") -> 0 | J18: =IFERROR($H18/$A$5,0) -> 0
A19: Física Quântica | B19: =SUMIF(Matriz!$B$2:$B$60,$A19,Matriz!$AE$2:$AE$60) -> 2 | C19: =COUNTIFS(Matriz!$B$2:$B$60,$A19,Matriz!$C$2:$C$60,"<>") -> 1 | D19: =SUMIF(Matriz!$B$2:$B$60,$A19,Matriz!$AF$2:$AF$60) -> 1 | E19: =IFERROR($B19/($C19*12),0) -> 0.16666667 | G19: Substack | H19: =SUM(INDEX(Matriz!$F$2:$Q$60,0,MATCH($G19,Matriz!$F$1:$Q$1,0))) -> 0 | I19: =COUNTIF(INDEX(Matriz!$R$2:$AC$60,0,MATCH($G19&" (link)",Matriz!$R$1:$AC$1,0)),"http*") -> 0 | J19: =IFERROR($H19/$A$5,0) -> 0
A20: Geometria | B20: =SUMIF(Matriz!$B$2:$B$60,$A20,Matriz!$AE$2:$AE$60) -> 14 | C20: =COUNTIFS(Matriz!$B$2:$B$60,$A20,Matriz!$C$2:$C$60,"<>") -> 7 | D20: =SUMIF(Matriz!$B$2:$B$60,$A20,Matriz!$AF$2:$AF$60) -> 8 | E20: =IFERROR($B20/($C20*12),0) -> 0.16666667 | G20: GitHub | H20: =SUM(INDEX(Matriz!$F$2:$Q$60,0,MATCH($G20,Matriz!$F$1:$Q$1,0))) -> 7 | I20: =COUNTIF(INDEX(Matriz!$R$2:$AC$60,0,MATCH($G20&" (link)",Matriz!$R$1:$AC$1,0)),"http*") -> 1 | J20: =IFERROR($H20/$A$5,0) -> 0.14893617
A21: Programação | B21: =SUMIF(Matriz!$B$2:$B$60,$A21,Matriz!$AE$2:$AE$60) -> 6 | C21: =COUNTIFS(Matriz!$B$2:$B$60,$A21,Matriz!$C$2:$C$60,"<>") -> 3 | D21: =SUMIF(Matriz!$B$2:$B$60,$A21,Matriz!$AF$2:$AF$60) -> 3 | E21: =IFERROR($B21/($C21*12),0) -> 0.16666667 | G21: Oz.io | H21: =SUM(INDEX(Matriz!$F$2:$Q$60,0,MATCH($G21,Matriz!$F$1:$Q$1,0))) -> 0 | I21: =COUNTIF(INDEX(Matriz!$R$2:$AC$60,0,MATCH($G21&" (link)",Matriz!$R$1:$AC$1,0)),"http*") -> 0 | J21: =IFERROR($H21/$A$5,0) -> 0
A22: Teoria dos Números | B22: =SUMIF(Matriz!$B$2:$B$60,$A22,Matriz!$AE$2:$AE$60) -> 4 | C22: =COUNTIFS(Matriz!$B$2:$B$60,$A22,Matriz!$C$2:$C$60,"<>") -> 2 | D22: =SUMIF(Matriz!$B$2:$B$60,$A22,Matriz!$AF$2:$AF$60) -> 2 | E22: =IFERROR($B22/($C22*12),0) -> 0.16666667 | G22: Oz Site | H22: =SUM(INDEX(Matriz!$F$2:$Q$60,0,MATCH($G22,Matriz!$F$1:$Q$1,0))) -> 0 | I22: =COUNTIF(INDEX(Matriz!$R$2:$AC$60,0,MATCH($G22&" (link)",Matriz!$R$1:$AC$1,0)),"http*") -> 0 | J22: =IFERROR($H22/$A$5,0) -> 0
A23: Warp Drive | B23: =SUMIF(Matriz!$B$2:$B$60,$A23,Matriz!$AE$2:$AE$60) -> 27 | C23: =COUNTIFS(Matriz!$B$2:$B$60,$A23,Matriz!$C$2:$C$60,"<>") -> 8 | D23: =SUMIF(Matriz!$B$2:$B$60,$A23,Matriz!$AF$2:$AF$60) -> 14 | E23: =IFERROR($B23/($C23*12),0) -> 0.28125 | G23: Curso | H23: =SUM(INDEX(Matriz!$F$2:$Q$60,0,MATCH($G23,Matriz!$F$1:$Q$1,0))) -> 0 | I23: =COUNTIF(INDEX(Matriz!$R$2:$AC$60,0,MATCH($G23&" (link)",Matriz!$R$1:$AC$1,0)),"http*") -> 0 | J23: =IFERROR($H23/$A$5,0) -> 0
A24: Total | B24: =SUM($B$12:$B$23) -> 111 | C24: =SUM($C$12:$C$23) -> 47 | D24: =SUM($D$12:$D$23) -> 59 | E24: =IFERROR($B$24/($C$24*12),0) -> 0.19680851 | G24: Total | H24: =SUM($H$12:$H$23) -> 111 | I24: =SUM($I$12:$I$23) -> 59 | J24: =IFERROR($H$24/($A$5*12),0) -> 0.19680851
A26: TOP 10 PROJETOS POR SAÍDAS CONCLUÍDAS | I26: PERIÓDICOS (pipeline de submissão)
A27: Projeto | D27: Tema | E27: Saídas | F27: Links | G27: Cobertura | I27: Indicador | K27: Valor
A28: =IFERROR(INDEX(Matriz!$C$2:$C$60,MATCH(ROWS($A$28:$A28),Matriz!$AH$2:$AH$60,0)),"") -> O problema do SAT que todos erraram: paradoxo das moedas e roda de Aristóteles | D28: =IFERROR(INDEX(Matriz!$B$2:$B$60,MATCH(ROWS($A$28:$A28),Matriz!$AH$2:$AH$60,0)),"") -> Física Clássica | E28: =IFERROR(INDEX(Matriz!$AE$2:$AE$60,MATCH(ROWS($A$28:$A28),Matriz!$AH$2:$AH$60,0)),"") -> 6 | F28: =IFERROR(INDEX(Matriz!$AF$2:$AF$60,MATCH(ROWS($A$28:$A28),Matriz!$AH$2:$AH$60,0)),"") -> 4 | G28: =IFERROR($E28/12,0) -> 0.5 | I28: Periódicos mapeados | K28: =COUNTIF(Periódicos!$A$2:$A$168,"<>") -> 167
A29: =IFERROR(INDEX(Matriz!$C$2:$C$60,MATCH(ROWS($A$28:$A29),Matriz!$AH$2:$AH$60,0)),"") -> Experimento de medição da densidade da água | D29: =IFERROR(INDEX(Matriz!$B$2:$B$60,MATCH(ROWS($A$28:$A29),Matriz!$AH$2:$AH$60,0)),"") -> Física Clássica | E29: =IFERROR(INDEX(Matriz!$AE$2:$AE$60,MATCH(ROWS($A$28:$A29),Matriz!$AH$2:$AH$60,0)),"") -> 4 | F29: =IFERROR(INDEX(Matriz!$AF$2:$AF$60,MATCH(ROWS($A$28:$A29),Matriz!$AH$2:$AH$60,0)),"") -> 3 | G29: =IFERROR($E29/12,0) -> 0.33333333 | I29: Fit 5 (prioridade) | K29: =COUNTIF(Periódicos!$I$2:$I$168,5) -> 27
A30: =IFERROR(INDEX(Matriz!$C$2:$C$60,MATCH(ROWS($A$28:$A30),Matriz!$AH$2:$AH$60,0)),"") -> Fluid dynamics in the warp drive spacetime geometry | D30: =IFERROR(INDEX(Matriz!$B$2:$B$60,MATCH(ROWS($A$28:$A30),Matriz!$AH$2:$AH$60,0)),"") -> Warp Drive | E30: =IFERROR(INDEX(Matriz!$AE$2:$AE$60,MATCH(ROWS($A$28:$A30),Matriz!$AH$2:$AH$60,0)),"") -> 4 | F30: =IFERROR(INDEX(Matriz!$AF$2:$AF$60,MATCH(ROWS($A$28:$A30),Matriz!$AH$2:$AH$60,0)),"") -> 2 | G30: =IFERROR($E30/12,0) -> 0.33333333 | I30: Fit ≥4 | K30: =COUNTIF(Periódicos!$I$2:$I$168,">=4") -> 113
A31: =IFERROR(INDEX(Matriz!$C$2:$C$60,MATCH(ROWS($A$28:$A31),Matriz!$AH$2:$AH$60,0)),"") -> Charged dust solutions for the warp drive spacetime | D31: =IFERROR(INDEX(Matriz!$B$2:$B$60,MATCH(ROWS($A$28:$A31),Matriz!$AH$2:$AH$60,0)),"") -> Warp Drive | E31: =IFERROR(INDEX(Matriz!$AE$2:$AE$60,MATCH(ROWS($A$28:$A31),Matriz!$AH$2:$AH$60,0)),"") -> 4 | F31: =IFERROR(INDEX(Matriz!$AF$2:$AF$60,MATCH(ROWS($A$28:$A31),Matriz!$AH$2:$AH$60,0)),"") -> 2 | G31: =IFERROR($E31/12,0) -> 0.33333333 | I31: Impact Factor médio | K31: =IFERROR(AVERAGE(Periódicos!$D$2:$D$168),0) -> 6.8288611
A32: =IFERROR(INDEX(Matriz!$C$2:$C$60,MATCH(ROWS($A$28:$A32),Matriz!$AH$2:$AH$60,0)),"") -> Perfect fluid warp drive solutions with the cosmological constant | D32: =IFERROR(INDEX(Matriz!$B$2:$B$60,MATCH(ROWS($A$28:$A32),Matriz!$AH$2:$AH$60,0)),"") -> Warp Drive | E32: =IFERROR(INDEX(Matriz!$AE$2:$AE$60,MATCH(ROWS($A$28:$A32),Matriz!$AH$2:$AH$60,0)),"") -> 4 | F32: =IFERROR(INDEX(Matriz!$AF$2:$AF$60,MATCH(ROWS($A$28:$A32),Matriz!$AH$2:$AH$60,0)),"") -> 2 | G32: =IFERROR($E32/12,0) -> 0.33333333 | I32: Área: matemática | K32: =COUNTIF(Periódicos!$E$2:$E$168,"matemática") -> 140
A33: =IFERROR(INDEX(Matriz!$C$2:$C$60,MATCH(ROWS($A$28:$A33),Matriz!$AH$2:$AH$60,0)),"") -> Warp drive dynamic solutions considering different fluid sources | D33: =IFERROR(INDEX(Matriz!$B$2:$B$60,MATCH(ROWS($A$28:$A33),Matriz!$AH$2:$AH$60,0)),"") -> Warp Drive | E33: =IFERROR(INDEX(Matriz!$AE$2:$AE$60,MATCH(ROWS($A$28:$A33),Matriz!$AH$2:$AH$60,0)),"") -> 4 | F33: =IFERROR(INDEX(Matriz!$AF$2:$AF$60,MATCH(ROWS($A$28:$A33),Matriz!$AH$2:$AH$60,0)),"") -> 2 | G33: =IFERROR($E33/12,0) -> 0.33333333 | I33: Área: física | K33: =COUNTIF(Periódicos!$E$2:$E$168,"física") -> 26
A34: =IFERROR(INDEX(Matriz!$C$2:$C$60,MATCH(ROWS($A$28:$A34),Matriz!$AH$2:$AH$60,0)),"") -> Matching the Alcubierre and Minkowski spacetimes. | D34: =IFERROR(INDEX(Matriz!$B$2:$B$60,MATCH(ROWS($A$28:$A34),Matriz!$AH$2:$AH$60,0)),"") -> Warp Drive | E34: =IFERROR(INDEX(Matriz!$AE$2:$AE$60,MATCH(ROWS($A$28:$A34),Matriz!$AH$2:$AH$60,0)),"") -> 4 | F34: =IFERROR(INDEX(Matriz!$AF$2:$AF$60,MATCH(ROWS($A$28:$A34),Matriz!$AH$2:$AH$60,0)),"") -> 2 | G34: =IFERROR($E34/12,0) -> 0.33333333 | I34: Área: data science | K34: =COUNTIF(Periódicos!$E$2:$E$168,"data science") -> 1
A35: =IFERROR(INDEX(Matriz!$C$2:$C$60,MATCH(ROWS($A$28:$A35),Matriz!$AH$2:$AH$60,0)),"") -> Dust content content solutions for the Alcubierre warp drive spacetime. | D35: =IFERROR(INDEX(Matriz!$B$2:$B$60,MATCH(ROWS($A$28:$A35),Matriz!$AH$2:$AH$60,0)),"") -> Warp Drive | E35: =IFERROR(INDEX(Matriz!$AE$2:$AE$60,MATCH(ROWS($A$28:$A35),Matriz!$AH$2:$AH$60,0)),"") -> 3 | F35: =IFERROR(INDEX(Matriz!$AF$2:$AF$60,MATCH(ROWS($A$28:$A35),Matriz!$AH$2:$AH$60,0)),"") -> 2 | G35: =IFERROR($E35/12,0) -> 0.25 | I35: Open Access declarado | K35: =COUNTIF(Periódicos!$K$2:$K$168,"Open Access*") -> 40
A36: =IFERROR(INDEX(Matriz!$C$2:$C$60,MATCH(ROWS($A$28:$A36),Matriz!$AH$2:$AH$60,0)),"") -> Resolvendo equação polinomial de quarta ordem e demonstrando um teorema de redução de ordem | D36: =IFERROR(INDEX(Matriz!$B$2:$B$60,MATCH(ROWS($A$28:$A36),Matriz!$AH$2:$AH$60,0)),"") -> Álgebra | E36: =IFERROR(INDEX(Matriz!$AE$2:$AE$60,MATCH(ROWS($A$28:$A36),Matriz!$AH$2:$AH$60,0)),"") -> 2 | F36: =IFERROR(INDEX(Matriz!$AF$2:$AF$60,MATCH(ROWS($A$28:$A36),Matriz!$AH$2:$AH$60,0)),"") -> 1 | G36: =IFERROR($E36/12,0) -> 0.16666667 | I36: Artigos planejados (Journal) | K36: =$H$13 -> 8
A37: =IFERROR(INDEX(Matriz!$C$2:$C$60,MATCH(ROWS($A$28:$A37),Matriz!$AH$2:$AH$60,0)),"") -> Resolvendo (polinômios): x³ + px + q é divisível por (x-a)², encontre a relação entre p e q. | D37: =IFERROR(INDEX(Matriz!$B$2:$B$60,MATCH(ROWS($A$28:$A37),Matriz!$AH$2:$AH$60,0)),"") -> Álgebra | E37: =IFERROR(INDEX(Matriz!$AE$2:$AE$60,MATCH(ROWS($A$28:$A37),Matriz!$AH$2:$AH$60,0)),"") -> 2 | F37: =IFERROR(INDEX(Matriz!$AF$2:$AF$60,MATCH(ROWS($A$28:$A37),Matriz!$AH$2:$AH$60,0)),"") -> 1 | G37: =IFERROR($E37/12,0) -> 0.16666667 | I37: Artigos com link (Journal) | K37: =$I$13 -> 8
A39: QUALIDADE DOS DADOS (itens a corrigir)
A40: Verificação | E40: Ocorrências
A41: Saídas marcadas como concluídas sem link | E41: =SUM(Matriz!$AI$2:$AI$60) -> 52
A42: Links registrados sem marcação de canal | E42: =SUM(Matriz!$AJ$2:$AJ$60) -> 0
A43: Projetos sem tema atribuído | E43: =COUNTIFS(Matriz!$C$2:$C$60,"<>",Matriz!$B$2:$B$60,"") -> 0
A44: Projetos em que o campo Saídas difere da soma dos canais | E44: =SUM(Matriz!$AK$2:$AK$60) -> 40
A45: Linhas com Saídas preenchidas sem título de projeto | E45: =COUNTIFS(Matriz!$C$2:$C$60,"",Matriz!$E$2:$E$60,">0") -> 12
...

Sheet Matriz
A1: ID | B1: Tema | C1: Título YouTube/Ideia | D1: Descrição | E1: Saídas | F1: arXiv/SSRN | G1: Journal | H1: Research Gate | I1: YouTube | J1: TikTok | K1: LinkedIn | L1: Newsletter LinkedIn | M1: Substack | N1: GitHub | O1: Oz.io | P1: Oz Site | Q1: Curso | R1: arXiv/SSRN (link) | S1: Journal (link) | T1: Research Gate (link) | U1: YouTube (link) | V1: TikTok (link) | W1: LinkedIn (link) | X1: Newsletter LinkedIn (link) | Y1: Substack (link) | Z1: GitHub (link) | AA1: Oz.io (link) | AB1: Oz Site (link) | AC1: Curso (link) | AE1: Saídas concluídas (soma canais) | AF1: Links registrados | AG1: Chave ordenação | AH1: Rank | AI1: Concluídas sem link | AJ1: Links sem marcação | AK1: Divergência campo Saídas
A2: 1 | B2: Álgebra | C2: Resolvendo equação polinomial de quarta ordem e demonstrando um teorema de redução de ordem | D2: Neste primeiro vídeo da série sobre raciocínio matemático: resolvo uma equação polinomial do quarto grau para um caso particular e desenvolvo um algoritmo para reduzir o grau desse polinômio pela metade através de uma substituição de variáveis. | E2: 1 | F2: 0 | G2: 0 | H2: 0 | I2: 1 | J2: 1 | K2: 0 | L2: 0 | M2: 0 | N2: 0 | O2: 0 | P2: 0 | Q2: 0 | R2: ------- | S2: ------- | T2: ------- | U2: https://www.youtube.com/watch?v=jdkhDn97CMA | V2: ------- | W2: ------- | X2: ------- | Y2: ------- | Z2: ------- | AA2: ------- | AB2: ------- | AC2: ------- | AE2: =IF($C2="","",SUM($F2:$Q2)) -> 2 | AF2: =IF($C2="","",COUNTIF($R2:$AC2,"http*")) -> 1 | AG2: =IF($C2="","",$AE2*1000+(1000-$A2)) -> 2999 | AH2: =IF($C2="","",RANK($AG2,$AG$2:$AG$60)) -> 9 | AI2: =IF($C2="","",MAX(0,$AE2-$AF2)) -> 1 | AJ2: =IF($C2="","",MAX(0,$AF2-$AE2)) -> 0 | AK2: =IF($C2="","",IF($E2<>$AE2,1,0)) -> 1
A3: 2 | B3: Álgebra | C3: Resolvendo (polinômios): x³ + px + q é divisível por (x-a)², encontre a relação entre p e q. | D3: Resolvendo o seguinte problema: f(x) = x³ + px + q é divisível por (x-a)² Encontre a relação entre p e q. | E3: 1 | F3: 0 | G3: 0 | H3: 0 | I3: 1 | J3: 1 | K3: 0 | L3: 0 | M3: 0 | N3: 0 | O3: 0 | P3: 0 | Q3: 0 | R3: ------- | S3: ------- | T3: ------- | U3: https://www.youtube.com/watch?v=RDFBAXc1P9E | V3: ------- | W3: ------- | X3: ------- | Y3: ------- | Z3: ------- | AA3: ------- | AB3: ------- | AC3: ------- | AE3: =IF($C3="","",SUM($F3:$Q3)) -> 2 | AF3: =IF($C3="","",COUNTIF($R3:$AC3,"http*")) -> 1 | AG3: =IF($C3="","",$AE3*1000+(1000-$A3)) -> 2998 | AH3: =IF($C3="","",RANK($AG3,$AG$2:$AG$60)) -> 10 | AI3: =IF($C3="","",MAX(0,$AE3-$AF3)) -> 1 | AJ3: =IF($C3="","",MAX(0,$AF3-$AE3)) -> 0 | AK3: =IF($C3="","",IF($E3<>$AE3,1,0)) -> 1
A4: 3 | B4: Análise de dados | C4: Como visualizar dados longitudinais: linhas, heatmaps e painéis | D4: Neste vídeo, há uma apresentação com alguns exemplos de gráficos para visualizar dados em painel (dados longitudinais). Arquivo pdf com a aula: https://github.com/ozsp12/ai_data_citizen/blob/main/dados_em_painel/tipos_graficos_dados_em_painel.pdf 00:00 Introdução – Importância das visualizações 00:40 Tipos de gráficos e estrutura do exemplo 01:09 Boas práticas e considerações de design 01:55 Gráfico de barras por mês do ano 02:57 Gráfico de barras empilhado 03:32 Gráfico de barras por produto 04:03 Gráfico de área 04:25 Gráfico de linha 04:51 Mapa de calor (Heatmap) | E4: 1 | F4: 0 | G4: 0 | H4: 0 | I4: 1 | J4: 1 | K4: 0 | L4: 0 | M4: 0 | N4: 0 | O4: 0 | P4: 0 | Q4: 0 | R4: ------- | S4: ------- | T4: ------- | U4: https://www.youtube.com/watch?v=Etwy8F1cmzA | V4: ------- | W4: ------- | X4: ------- | Y4: ------- | Z4: ------- | AA4: ------- | AB4: ------- | AC4: ------- | AE4: =IF($C4="","",SUM($F4:$Q4)) -> 2 | AF4: =IF($C4="","",COUNTIF($R4:$AC4,"http*")) -> 1 | AG4: =IF($C4="","",$AE4*1000+(1000-$A4)) -> 2997 | AH4: =IF($C4="","",RANK($AG4,$AG$2:$AG$60)) -> 11 | AI4: =IF($C4="","",MAX(0,$AE4-$AF4)) -> 1 | AJ4: =IF($C4="","",MAX(0,$AF4-$AE4)) -> 0 | AK4: =IF($C4="","",IF($E4<>$AE4,1,0)) -> 1
A5: 4 | B5: Análise de dados | C5: "Quick and dirty": análise de dados com Python - Precificação e elasticidade. | D5: Neste vídeo, inicio uma série que vou chamar de “Quick and Dirty”, na qual apresento ferramentas de análise de dados para responder rapidamente a perguntas de negócio, usando modelos matemáticos e estatísticos de forma menos rigorosa. A famosa regra 80–20 entre rigor e valor gerado: 20% de rigor e 80% de valor gerado. Como prometido, além de ensinar Python, vou procurar compartilhar algumas ferramentas matemáticas, estatísticas e de análise de dados que conheço, bem como conceitos teóricos de diversas áreas, como microeconomia, macroeconomia, séries temporais, pesquisa operacional, entre outras. Jupyter Notebook: https://github.com/ozsp12/ai_data_citizen/tree/main/quick_dirty_analytics GitHub (Introdução à Programação): https://github.com/ozsp12/programacao_introducao/tree/main | E5: 1 | F5: 0 | G5: 0 | H5: 0 | I5: 1 | J5: 1 | K5: 0 | L5: 0 | M5: 0 | N5: 0 | O5: 0 | P5: 0 | Q5: 0 | R5: ------- | S5: ------- | T5: ------- | U5: https://www.youtube.com/watch?v=Vn45DCpdXNw | V5: ------- | W5: ------- | X5: ------- | Y5: ------- | Z5: ------- | AA5: ------- | AB5: ------- | AC5: ------- | AE5: =IF($C5="","",SUM($F5:$Q5)) -> 2 | AF5: =IF($C5="","",COUNTIF($R5:$AC5,"http*")) -> 1 | AG5: =IF($C5="","",$AE5*1000+(1000-$A5)) -> 2996 | AH5: =IF($C5="","",RANK($AG5,$AG$2:$AG$60)) -> 12 | AI5: =IF($C5="","",MAX(0,$AE5-$AF5)) -> 1 | AJ5: =IF($C5="","",MAX(0,$AF5-$AE5)) -> 0 | AK5: =IF($C5="","",IF($E5<>$AE5,1,0)) -> 1
A6: 5 | B6: Análise de dados | C6: Aula "trilha rápida do analista de dados": exemplos de funções (Python, SQL e DAX) muito utilizadas. | D6: Neste vídeo, eu ensino como utilizar algumas funções de Python, SQL e DAX (Power BI), úteis e amplamente utilizadas no dia a dia de um analista de dados. A ideia é proporcionar uma aula para que cidadãos dos dados se familiarizem com a linguagem de programação de alto nível, a manipulação de dados, os bancos de dados e as visualizações. Link do Notebook e PBIX no GitHub: https://github.com/ozsp12/ai_data_citizen/tree/main/fast_track SQL: SELECT FROM WHERE ORDER BY SUM(), COUNT(), AVG() GROUP BY CREATE, INSERT, DELETE Python (pandas): import pandas as pd pd.read_csv() df.head() df.tail() df.info() df.describe() df['coluna'] df[df['coluna'] "maior que" x] df.groupby() df.sort_values() df.isnull().sum() df.fillna() df.dropna() DAX (Power BI): CALCULATE() FILTER() ALL() SUM() COUNT() DIVIDE() IF() SWITCH() VALUES() RELATED() | E6: 1 | F6: 0 | G6: 0 | H6: 0 | I6: 1 | J6: 1 | K6: 0 | L6: 0 | M6: 0 | N6: 0 | O6: 0 | P6: 0 | Q6: 0 | R6: ------- | S6: ------- | T6: ------- | U6: https://www.youtube.com/watch?v=dLDmXewxwpA | V6: ------- | W6: ------- | X6: ------- | Y6: ------- | Z6: ------- | AA6: ------- | AB6: ------- | AC6: ------- | AE6: =IF($C6="","",SUM($F6:$Q6)) -> 2 | AF6: =IF($C6="","",COUNTIF($R6:$AC6,"http*")) -> 1 | AG6: =IF($C6="","",$AE6*1000+(1000-$A6)) -> 2995 | AH6: =IF($C6="","",RANK($AG6,$AG$2:$AG$60)) -> 13 | AI6: =IF($C6="","",MAX(0,$AE6-$AF6)) -> 1 | AJ6: =IF($C6="","",MAX(0,$AF6-$AE6)) -> 0 | AK6: =IF($C6="","",IF($E6<>$AE6,1,0)) -> 1
A7: 6 | B7: Análise matemática | C7: Derivative of the exponential function via the limit definition | D7: In this video, we derive the exponential function from first principles using the limit definition of the derivative. Starting with $f(x)=a^x$, we examine the increment of the function, reorganize the expression algebraically, and obtain the derivative step by step in a clear and rigorous way. This derivation is a classic result of differential calculus and helps deepen understanding of exponential functions and their role in mathematics. This video is intended for students and anyone interested in: calculus, limits, derivatives, exponential functions, and mathematical reasoning. References [1] Stewart, J. Calculus: Early Transcendentals. 8th ed., Cengage Learning, 2016. [2] Hass, J. R., Heil, C. E., Weir, M. D., and Bogacki, P. Thomas’ Calculus: Early Transcendentals, SI Units. 15th ed., Pearson, 2023. [3] Spivak, M. Calculus. 4th ed., Publish or Perish, Inc., 2008. [4] Apostol, T. M. Calculus, Volume 1: One-Variable Calculus, with an Introduction to Linear Algebra. 2nd ed., John Wiley & Sons, 1991. [5] Strang, G. Calculus. 2nd ed., Wellesley-Cambridge Press, 2010. #Calculus #Derivative #ExponentialFunction #Mathematics #Limits #MathEducation | E7: 1 | F7: 0 | G7: 0 | H7: 0 | I7: 1 | J7: 1 | K7: 0 | L7: 0 | M7: 0 | N7: 0 | O7: 0 | P7: 0 | Q7: 0 | R7: ------- | S7: ------- | T7: ------- | U7: https://www.youtube.com/watch?v=RBGLS71u6wI | V7: ------- | W7: ------- | X7: ------- | Y7: ------- | Z7: ------- | AA7: ------- | AB7: ------- | AC7: ------- | AE7: =IF($C7="","",SUM($F7:$Q7)) -> 2 | AF7: =IF($C7="","",COUNTIF($R7:$AC7,"http*")) -> 1 | AG7: =IF($C7="","",$AE7*1000+(1000-$A7)) -> 2994 | AH7: =IF($C7="","",RANK($AG7,$AG$2:$AG$60)) -> 14 | AI7: =IF($C7="","",MAX(0,$AE7-$AF7)) -> 1 | AJ7: =IF($C7="","",MAX(0,$AF7-$AE7)) -> 0 | AK7: =IF($C7="","",IF($E7<>$AE7,1,0)) -> 1
A8: 7 | B8: Análise matemática | C8: Why the Gradient Is Orthogonal to Level Surfaces | D8: In this video, I present a visual explanation of the relationship between linear algebra and differential calculus: vectors orthogonal to the same nonzero vector lie in the same plane. In R³, given a non-zero vector c, the set of all vectors x such that the inner product between x and c is equal to zero forms a two-dimensional vector subspace. Geometrically, this subspace is a plane perpendicular to the vector c. Thus, if three vectors u, v, and w simultaneously satisfy: [u , c] = 0, [v , c] = 0, [w , c] = 0. where [ , ] denotes the usual inner product. Then all three belong to the same plane, perpendicular to c. Since this plane has dimension 2, three vectors contained in it cannot be linearly independent. Therefore, u, v, and w are necessarily linearly dependent. This idea arises naturally in geometry and differential calculus. When we have a level surface, that is, a surface defined by the points at which a function g(x, y, z) assumes a constant value, any curve contained in that surface preserves this value along its path. By differentiating this condition using the chain rule, we obtain that the inner product between the gradient of g and the tangent vector to the curve is zero. In other words, the tangent vector to the curve is orthogonal to the gradient of the function. Hence, the gradient points in the normal direction to the level surface. At the intersection of two level surfaces, the intersection curve has a tangent vector that is simultaneously orthogonal to both gradients. For this reason, this tangent vector is parallel to the cross product of the gradients of the two functions. References [1] Apostol, T. M. (1969). Calculus, Volume II: Multi-variable calculus and linear algebra, with applications to differential equations and probability (2nd ed.). John Wiley & Sons. [2] Axler, S. (2015). Linear algebra done right (3rd ed.). Springer. [3] do Carmo, M. P. (1976). Differential geometry of curves and surfaces. Prentice-Hall. [4] Hoffman, K., & Kunze, R. (1971). Linear algebra (2nd ed.). Prentice-Hall. [5] Lee, J. M. (2013). Introduction to smooth manifolds (2nd ed.). Springer. [6] Marsden, J. E., & Tromba, A. J. (2003). Vector calculus (5th ed.). W. H. Freeman. [7] Spivak, M. (1965). Calculus on manifolds: A modern approach to classical theorems of advanced calculus. W. A. Benjamin. [8] Strang, G. (2016). Introduction to linear algebra (5th ed.). Wellesley-Cambridge Press. | E8: 1 | F8: 0 | G8: 0 | H8: 0 | I8: 1 | J8: 1 | K8: 0 | L8: 0 | M8: 0 | N8: 0 | O8: 0 | P8: 0 | Q8: 0 | R8: ------- | S8: ------- | T8: ------- | U8: https://www.youtube.com/watch?v=E-RCxwW9PBw | V8: ------- | W8: ------- | X8: ------- | Y8: ------- | Z8: ------- | AA8: ------- | AB8: ------- | AC8: ------- | AE8: =IF($C8="","",SUM($F8:$Q8)) -> 2 | AF8: =IF($C8="","",COUNTIF($R8:$AC8,"http*")) -> 1 | AG8: =IF($C8="","",$AE8*1000+(1000-$A8)) -> 2993 | AH8: =IF($C8="","",RANK($AG8,$AG$2:$AG$60)) -> 15 | AI8: =IF($C8="","",MAX(0,$AE8-$AF8)) -> 1 | AJ8: =IF($C8="","",MAX(0,$AF8-$AE8)) -> 0 | AK8: =IF($C8="","",IF($E8<>$AE8,1,0)) -> 1
A9: 8 | B9: Análise matemática | C9: Por que o gradiente é perpendicular às superfícies de nível? | D9: Neste vídeo, organizei uma explicação visual sobre a relação entre álgebra linear e cálculo diferencial: vetores ortogonais a um mesmo vetor não nulo pertencem ao mesmo plano. Em R³, dado um vetor c não nulo, o conjunto de todos os vetores x tais que o produto escalar entre x e c é igual a zero forma um subespaço vetorial de dimensão 2. Geometricamente, esse subespaço é um plano perpendicular ao vetor c. Assim, se três vetores u, v e w satisfazem simultaneamente: [u , c] = 0, [v , c] = 0, [w , c] = 0. Sendo [ , ] o produto escalar usual. Então, os três pertencem ao mesmo plano, perpendicular a c. Como esse plano tem dimensão 2, três vetores nele não podem ser linearmente independentes. Portanto, u, v e w são necessariamente linearmente dependentes. Essa ideia surge naturalmente na geometria e no cálculo diferencial. Quando temos uma superfície de nível, isto é, uma superfície definida pelos pontos em que uma função g(x, y, z) assume um valor constante, qualquer curva contida nessa superfície mantém esse valor ao longo de seu trajeto. Ao derivar essa condição pela regra da cadeia, obtemos que o produto escalar entre o gradiente de g e o vetor tangente à curva é nulo. Em outras palavras, o vetor tangente à curva é ortogonal ao gradiente da função. Logo, o gradiente aponta na direção normal à superfície de nível. No caso da interseção de duas superfícies de nível, a curva de interseção possui um vetor tangente que é simultaneamente ortogonal a ambos os gradientes. Por isso, esse vetor tangente é paralelo ao produto vetorial dos gradientes das duas funções. Referências [1] Apostol, T. M. (1969). Calculus, Volume II: Multi-variable calculus and linear algebra, with applications to differential equations and probability (2nd ed.). John Wiley & Sons. [2] Axler, S. (2015). Linear algebra done right (3rd ed.). Springer. [3] do Carmo, M. P. (1976). Differential geometry of curves and surfaces. Prentice-Hall. [4] Hoffman, K., & Kunze, R. (1971). Linear algebra (2nd ed.). Prentice-Hall. [5] Lee, J. M. (2013). Introduction to smooth manifolds (2nd ed.). Springer. [6] Marsden, J. E., & Tromba, A. J. (2003). Vector calculus (5th ed.). W. H. Freeman. [7] Spivak, M. (1965). Calculus on manifolds: A modern approach to classical theorems of advanced calculus. W. A. Benjamin. [8] Strang, G. (2016). Introduction to linear algebra (5th ed.). Wellesley-Cambridge Press. | E9: 1 | F9: 0 | G9: 0 | H9: 0 | I9: 1 | J9: 1 | K9: 0 | L9: 0 | M9: 0 | N9: 0 | O9: 0 | P9: 0 | Q9: 0 | R9: ------- | S9: ------- | T9: ------- | U9: https://www.youtube.com/watch?v=jMSWzqKGbBs | V9: ------- | W9: ------- | X9: ------- | Y9: ------- | Z9: ------- | AA9: ------- | AB9: ------- | AC9: ------- | AE9: =IF($C9="","",SUM($F9:$Q9)) -> 2 | AF9: =IF($C9="","",COUNTIF($R9:$AC9,"http*")) -> 1 | AG9: =IF($C9="","",$AE9*1000+(1000-$A9)) -> 2992 | AH9: =IF($C9="","",RANK($AG9,$AG$2:$AG$60)) -> 16 | AI9: =IF($C9="","",MAX(0,$AE9-$AF9)) -> 1 | AJ9: =IF($C9="","",MAX(0,$AF9-$AE9)) -> 0 | AK9: =IF($C9="","",IF($E9<>$AE9,1,0)) -> 1
A10: 9 | B10: Análise matemática | C10: Benderama: banach-tarski machine and quantum Bender. Explanation of the harmonic series divergence. | D10: Neste vídeo, uso o episódio 17 da sexta temporada de Futurama, “Benderama”, para explicar a série harmônica e demonstrar por que ela é divergente. No episódio, o Professor Farnsworth apresenta uma expressão matemática para calcular a massa total acumulada dos Benders ao longo de sucessivos processos de duplicação. Embora a massa individual de cada cópia diminua rapidamente, o número de Benders cresce exponencialmente. Ao simplificar a expressão, obtém-se a série harmônica, cuja soma cresce indefinidamente. 00:00 Introdução: matemática em *Futurama* 00:26 Trecho do episódio “Benderama” 01:39 O paradoxo de Banach–Tarski e a premissa do episódio 04:20 A equação apresentada pelo Professor Farnsworth 06:29 Dedução da massa dos Benders 13:47 Da soma das massas à série harmônica 15:29 Por que a série é divergente 17:09 Número de Benders, massa individual e efeitos subatômicos 20:22 Encerramento link para apresentação do vídeo e para o notebook Jupyter com o código que gera os gráficos apresentados no vídeo: https://github.com/ozsp12/math_elementary/tree/main/futurama_banach_tarski Referências 1. OpenStax, Calculus, Volume 2 (OpenStax, Rice University, Houston, 2016), Secs. 5.2–5.3. 2. S. Abbott, Understanding Analysis, 2nd ed. (Springer, New York, 2015). 3. T. M. Apostol, Mathematical Analysis: A Modern Approach to Advanced Calculus, 2nd ed. (Addison-Wesley, Reading, MA, 1974). 4. W. Rudin, Principles of Mathematical Analysis, 3rd ed. (McGraw-Hill, New York, 1976). 5. G. B. Folland, Real Analysis: Modern Techniques and Their Applications, 2nd ed. (Wiley, New York, 1999). 6. G. Tomkowicz and S. Wagon, The Banach–Tarski Paradox, 2nd ed. (Cambridge University Press, Cambridge, 2016). 7. S. Banach and A. Tarski, “Sur la décomposition des ensembles de points en parties respectivement congruentes,” Fund. Math. 6, 244–277 (1924). 8. K. Buchhorn, “The Banach–Tarski Paradox,” arXiv:2108.05714 (2021). 9. S. Singh, Os Segredos Matemáticos dos Simpsons (Record, Rio de Janeiro, 2016). | E10: 1 | F10: 0 | G10: 0 | H10: 0 | I10: 1 | J10: 1 | K10: 0 | L10: 0 | M10: 0 | N10: 0 | O10: 0 | P10: 0 | Q10: 0 | R10: ------- | S10: ------- | T10: ------- | U10: https://www.youtube.com/watch?v=zb1tEaJ2yFc | V10: ------- | W10: ------- | X10: ------- | Y10: ------- | Z10: ------- | AA10: ------- | AB10: ------- | AC10: ------- | AE10: =IF($C10="","",SUM($F10:$Q10)) -> 2 | AF10: =IF($C10="","",COUNTIF($R10:$AC10,"http*")) -> 1 | AG10: =IF($C10="","",$AE10*1000+(1000-$A10)) -> 2991 | AH10: =IF($C10="","",RANK($AG10,$AG$2:$AG$60)) -> 17 | AI10: =IF($C10="","",MAX(0,$AE10-$AF10)) -> 1 | AJ10: =IF($C10="","",MAX(0,$AF10-$AE10)) -> 0 | AK10: =IF($C10="","",IF($E10<>$AE10,1,0)) -> 1
A11: 10 | B11: Análise matemática | C11: Questão Dissertativa do IME de 2026: uma demonstração que engana muita gente. Desafiadora! | D11: Neste vídeo, resolvo a questão 8 do segundo dia do exame do IME 2025/2026. A questão parece desafiadora, mas, na verdade, é bastante simples; ainda assim, ela esconde vários conceitos interessantes, que são discutidos ao longo do vídeo. Como o teorema do ponto fixo de Banach (1922). Exames do IME https://inscricoes.ime.eb.br/cfg/ Link para a prova de Matemática do IME https://inscricoes.ime.eb.br/documentos/Prova_Discursiva_de_Matem%C3%A1tica.pdf Link para paper pedagógico sobre a resolução (em inglês) https://papers.ssrn.com/sol3/papers.cfm?abstract_id=6779078 0:00 Introdução e apresentação da questão 0:19 Enunciado do problema 0:30 Por que a questão parece mais difícil do que é 2:31 Definição do seno hiperbólico 3:15 Resolvendo a equação para obter o arco-seno hiperbólico 6:24 Identificação da expressão logarítmica 7:29 Reescrevendo o sistema com uma função auxiliar 9:16 Ideia de ponto fixo 11:17 Interpretação por sequência iterativa 13:19 Consequência: x = y = z 14:35 Prova da unicidade da solução 17:35 Demonstração por contradição 20:34 Comentário final sobre o valor conceitual da questão 22:00 Encerramento | E11: 1 | F11: 0 | G11: 0 | H11: 0 | I11: 1 | J11: 1 | K11: 0 | L11: 0 | M11: 0 | N11: 0 | O11: 0 | P11: 0 | Q11: 0 | R11: ------- | S11: ------- | T11: ------- | U11: https://www.youtube.com/watch?v=oY2PUGaeMuw | V11: ------- | W11: ------- | X11: ------- | Y11: ------- | Z11: ------- | AA11: ------- | AB11: ------- | AC11: ------- | AE11: =IF($C11="","",SUM($F11:$Q11)) -> 2 | AF11: =IF($C11="","",COUNTIF($R11:$AC11,"http*")) -> 1 | AG11: =IF($C11="","",$AE11*1000+(1000-$A11)) -> 2990 | AH11: =IF($C11="","",RANK($AG11,$AG$2:$AG$60)) -> 18 | AI11: =IF($C11="","",MAX(0,$AE11-$AF11)) -> 1 | AJ11: =IF($C11="","",MAX(0,$AF11-$AE11)) -> 0 | AK11: =IF($C11="","",IF($E11<>$AE11,1,0)) -> 1
A12: 11 | B12: Análise matemática | C12: Desigualdade de Cauchy–Schwarz: uma demonstração simples para estudantes avançados do ensino médio. | D12: Neste vídeo, demonstro a desigualdade de Cauchy–Schwarz em um contexto de análise real e sob a perspectiva da teoria dos números, sem recorrer a conceitos de espaços métricos e de normas. A demonstração é acessível a estudantes avançados do ensino médio. | E12: 1 | F12: 0 | G12: 0 | H12: 0 | I12: 1 | J12: 1 | K12: 0 | L12: 0 | M12: 0 | N12: 0 | O12: 0 | P12: 0 | Q12: 0 | R12: ------- | S12: ------- | T12: ------- | U12: https://www.youtube.com/watch?v=5UVnLilScIg | V12: ------- | W12: ------- | X12: ------- | Y12: ------- | Z12: ------- | AA12: ------- | AB12: ------- | AC12: ------- | AE12: =IF($C12="","",SUM($F12:$Q12)) -> 2 | AF12: =IF($C12="","",COUNTIF($R12:$AC12,"http*")) -> 1 | AG12: =IF($C12="","",$AE12*1000+(1000-$A12)) -> 2989 | AH12: =IF($C12="","",RANK($AG12,$AG$2:$AG$60)) -> 19 | AI12: =IF($C12="","",MAX(0,$AE12-$AF12)) -> 1 | AJ12: =IF($C12="","",MAX(0,$AF12-$AE12)) -> 0 | AK12: =IF($C12="","",IF($E12<>$AE12,1,0)) -> 1
A13: 12 | B13: Análise matemática | C13: Demonstração da desigualdade matemática (exercício 2.7 do livro The Cauchy-Schwarz Master Class). | D13: Neste vídeo resolvo o exercício 2.7 do livro Cauchy-Schwarz Master-Class. O enunciado do problema é o seguinte: dados x, y, z ≥ 0: xyz ≥ 1 → (1 + x)(1 + y)(1 + z) ≥ 8. E eu acabo discutindo e generalizando o problema. Parte do vídeo é improvisada, pois fui pensando enquanto gravava e acabei fazendo algumas afirmações sem refletir profundamente, que talvez estejam incorretas ou incompletas. Porém, um dos objetivos do meu canal é demonstrar como pesquisadores profissionais pensam e atacam problemas, mesmo que sejam problemas de fixação de conceitos. Steele, J. M. (2004). The Cauchy-Schwarz Master Class: An Introduction to the Art of Mathematical Inequalities. Cambridge University Press. DOI: https://doi.org/10.1017/CBO9780511817106. https://www.cambridge.org/core/books/cauchyschwarz-master-class/A444E291C6E5928ADB2DD9F37C4C6EB8 | E13: 1 | F13: 0 | G13: 0 | H13: 0 | I13: 1 | J13: 1 | K13: 0 | L13: 0 | M13: 0 | N13: 0 | O13: 0 | P13: 0 | Q13: 0 | R13: ------- | S13: ------- | T13: ------- | U13: https://www.youtube.com/watch?v=MXczcfmpxGY | V13: ------- | W13: ------- | X13: ------- | Y13: ------- | Z13: ------- | AA13: ------- | AB13: ------- | AC13: ------- | AE13: =IF($C13="","",SUM($F13:$Q13)) -> 2 | AF13: =IF($C13="","",COUNTIF($R13:$AC13,"http*")) -> 1 | AG13: =IF($C13="","",$AE13*1000+(1000-$A13)) -> 2988 | AH13: =IF($C13="","",RANK($AG13,$AG$2:$AG$60)) -> 20 | AI13: =IF($C13="","",MAX(0,$AE13-$AF13)) -> 1 | AJ13: =IF($C13="","",MAX(0,$AF13-$AE13)) -> 0 | AK13: =IF($C13="","",IF($E13<>$AE13,1,0)) -> 1
... A48: 47 | B48: algebra | C48: 10th-degree polynomial equation | D48: 10th-degree polynomial equation | E48: 1 | F48: 0 | G48: 0 | H48: 0 | I48: 1 | J48: 1 | K48: 0 | L48: 0 | M48: 0 | N48: 0 | O48: 0 | P48: 0 | Q48: 0 | R48: ------- | S48: ------- | T48: ------- | U48: https://www.youtube.com/watch?v=mJsv_uLeNgU | V48: ------- | W48: ------- | X48: ------- | Y48: ------- | Z48: ------- | AA48: ------- | AB48: ------- | AC48: ------- | AE48: =IF($C48="","",SUM($F48:$Q48)) -> 2 | AF48: =IF($C48="","",COUNTIF($R48:$AC48,"http*")) -> 1 | AG48: =IF($C48="","",$AE48*1000+(1000-$A48)) -> 2953 | AH48: =IF($C48="","",RANK($AG48,$AG$2:$AG$60)) -> 47 | AI48: =IF($C48="","",MAX(0,$AE48-$AF48)) -> 1 | AJ48: =IF($C48="","",MAX(0,$AF48-$AE48)) -> 0 | AK48: =IF($C48="","",IF($E48<>$AE48,1,0)) -> 1
A49: 48 | E49: 1 | F49: 0 | G49: 0 | H49: 0 | I49: 0 | J49: 0 | K49: 0 | L49: 0 | M49: 0 | N49: 0 | O49: 0 | P49: 0 | Q49: 0 | R49: ------- | S49: ------- | T49: ------- | U49: ------- | V49: ------- | W49: ------- | X49: ------- | Y49: ------- | Z49: ------- | AA49: ------- | AB49: ------- | AC49: ------- | AE49: =IF($C49="","",SUM($F49:$Q49)) | AF49: =IF($C49="","",COUNTIF($R49:$AC49,"http*")) | AG49: =IF($C49="","",$AE49*1000+(1000-$A49)) | AH49: =IF($C49="","",RANK($AG49,$AG$2:$AG$60)) | AI49: =IF($C49="","",MAX(0,$AE49-$AF49)) | AJ49: =IF($C49="","",MAX(0,$AF49-$AE49)) | AK49: =IF($C49="","",IF($E49<>$AE49,1,0))
A50: 49 | E50: 1 | F50: 0 | G50: 0 | H50: 0 | I50: 0 | J50: 0 | K50: 0 | L50: 0 | M50: 0 | N50: 0 | O50: 0 | P50: 0 | Q50: 0 | R50: ------- | S50: ------- | T50: ------- | U50: ------- | V50: ------- | W50: ------- | X50: ------- | Y50: ------- | Z50: ------- | AA50: ------- | AB50: ------- | AC50: ------- | AE50: =IF($C50="","",SUM($F50:$Q50)) | AF50: =IF($C50="","",COUNTIF($R50:$AC50,"http*")) | AG50: =IF($C50="","",$AE50*1000+(1000-$A50)) | AH50: =IF($C50="","",RANK($AG50,$AG$2:$AG$60)) | AI50: =IF($C50="","",MAX(0,$AE50-$AF50)) | AJ50: =IF($C50="","",MAX(0,$AF50-$AE50)) | AK50: =IF($C50="","",IF($E50<>$AE50,1,0))
A51: 50 | E51: 1 | F51: 0 | G51: 0 | H51: 0 | I51: 0 | J51: 0 | K51: 0 | L51: 0 | M51: 0 | N51: 0 | O51: 0 | P51: 0 | Q51: 0 | R51: ------- | S51: ------- | T51: ------- | U51: ------- | V51: ------- | W51: ------- | X51: ------- | Y51: ------- | Z51: ------- | AA51: ------- | AB51: ------- | AC51: ------- | AE51: =IF($C51="","",SUM($F51:$Q51)) | AF51: =IF($C51="","",COUNTIF($R51:$AC51,"http*")) | AG51: =IF($C51="","",$AE51*1000+(1000-$A51)) | AH51: =IF($C51="","",RANK($AG51,$AG$2:$AG$60)) | AI51: =IF($C51="","",MAX(0,$AE51-$AF51)) | AJ51: =IF($C51="","",MAX(0,$AF51-$AE51)) | AK51: =IF($C51="","",IF($E51<>$AE51,1,0))
A52: 51 | E52: 1 | F52: 0 | G52: 0 | H52: 0 | I52: 0 | J52: 0 | K52: 0 | L52: 0 | M52: 0 | N52: 0 | O52: 0 | P52: 0 | Q52: 0 | R52: ------- | S52: ------- | T52: ------- | U52: ------- | V52: ------- | W52: ------- | X52: ------- | Y52: ------- | Z52: ------- | AA52: ------- | AB52: ------- | AC52: ------- | AE52: =IF($C52="","",SUM($F52:$Q52)) | AF52: =IF($C52="","",COUNTIF($R52:$AC52,"http*")) | AG52: =IF($C52="","",$AE52*1000+(1000-$A52)) | AH52: =IF($C52="","",RANK($AG52,$AG$2:$AG$60)) | AI52: =IF($C52="","",MAX(0,$AE52-$AF52)) | AJ52: =IF($C52="","",MAX(0,$AF52-$AE52)) | AK52: =IF($C52="","",IF($E52<>$AE52,1,0))
A53: 52 | E53: 1 | F53: 0 | G53: 0 | H53: 0 | I53: 0 | J53: 0 | K53: 0 | L53: 0 | M53: 0 | N53: 0 | O53: 0 | P53: 0 | Q53: 0 | R53: ------- | S53: ------- | T53: ------- | U53: ------- | V53: ------- | W53: ------- | X53: ------- | Y53: ------- | Z53: ------- | AA53: ------- | AB53: ------- | AC53: ------- | AE53: =IF($C53="","",SUM($F53:$Q53)) | AF53: =IF($C53="","",COUNTIF($R53:$AC53,"http*")) | AG53: =IF($C53="","",$AE53*1000+(1000-$A53)) | AH53: =IF($C53="","",RANK($AG53,$AG$2:$AG$60)) | AI53: =IF($C53="","",MAX(0,$AE53-$AF53)) | AJ53: =IF($C53="","",MAX(0,$AF53-$AE53)) | AK53: =IF($C53="","",IF($E53<>$AE53,1,0))
A54: 53 | E54: 1 | F54: 0 | G54: 0 | H54: 0 | I54: 0 | J54: 0 | K54: 0 | L54: 0 | M54: 0 | N54: 0 | O54: 0 | P54: 0 | Q54: 0 | R54: ------- | S54: ------- | T54: ------- | U54: ------- | V54: ------- | W54: ------- | X54: ------- | Y54: ------- | Z54: ------- | AA54: ------- | AB54: ------- | AC54: ------- | AE54: =IF($C54="","",SUM($F54:$Q54)) | AF54: =IF($C54="","",COUNTIF($R54:$AC54,"http*")) | AG54: =IF($C54="","",$AE54*1000+(1000-$A54)) | AH54: =IF($C54="","",RANK($AG54,$AG$2:$AG$60)) | AI54: =IF($C54="","",MAX(0,$AE54-$AF54)) | AJ54: =IF($C54="","",MAX(0,$AF54-$AE54)) | AK54: =IF($C54="","",IF($E54<>$AE54,1,0))
A55: 54 | E55: 1 | F55: 0 | G55: 0 | H55: 0 | I55: 0 | J55: 0 | K55: 0 | L55: 0 | M55: 0 | N55: 0 | O55: 0 | P55: 0 | Q55: 0 | R55: ------- | S55: ------- | T55: ------- | U55: ------- | V55: ------- | W55: ------- | X55: ------- | Y55: ------- | Z55: ------- | AA55: ------- | AB55: ------- | AC55: ------- | AE55: =IF($C55="","",SUM($F55:$Q55)) | AF55: =IF($C55="","",COUNTIF($R55:$AC55,"http*")) | AG55: =IF($C55="","",$AE55*1000+(1000-$A55)) | AH55: =IF($C55="","",RANK($AG55,$AG$2:$AG$60)) | AI55: =IF($C55="","",MAX(0,$AE55-$AF55)) | AJ55: =IF($C55="","",MAX(0,$AF55-$AE55)) | AK55: =IF($C55="","",IF($E55<>$AE55,1,0))
A56: 55 | E56: 1 | F56: 0 | G56: 0 | H56: 0 | I56: 0 | J56: 0 | K56: 0 | L56: 0 | M56: 0 | N56: 0 | O56: 0 | P56: 0 | Q56: 0 | R56: ------- | S56: ------- | T56: ------- | U56: ------- | V56: ------- | W56: ------- | X56: ------- | Y56: ------- | Z56: ------- | AA56: ------- | AB56: ------- | AC56: ------- | AE56: =IF($C56="","",SUM($F56:$Q56)) | AF56: =IF($C56="","",COUNTIF($R56:$AC56,"http*")) | AG56: =IF($C56="","",$AE56*1000+(1000-$A56)) | AH56: =IF($C56="","",RANK($AG56,$AG$2:$AG$60)) | AI56: =IF($C56="","",MAX(0,$AE56-$AF56)) | AJ56: =IF($C56="","",MAX(0,$AF56-$AE56)) | AK56: =IF($C56="","",IF($E56<>$AE56,1,0))
A57: 56 | E57: 1 | F57: 0 | G57: 0 | H57: 0 | I57: 0 | J57: 0 | K57: 0 | L57: 0 | M57: 0 | N57: 0 | O57: 0 | P57: 0 | Q57: 0 | R57: ------- | S57: ------- | T57: ------- | U57: ------- | V57: ------- | W57: ------- | X57: ------- | Y57: ------- | Z57: ------- | AA57: ------- | AB57: ------- | AC57: ------- | AE57: =IF($C57="","",SUM($F57:$Q57)) | AF57: =IF($C57="","",COUNTIF($R57:$AC57,"http*")) | AG57: =IF($C57="","",$AE57*1000+(1000-$A57)) | AH57: =IF($C57="","",RANK($AG57,$AG$2:$AG$60)) | AI57: =IF($C57="","",MAX(0,$AE57-$AF57)) | AJ57: =IF($C57="","",MAX(0,$AF57-$AE57)) | AK57: =IF($C57="","",IF($E57<>$AE57,1,0))
A58: 57 | E58: 1 | F58: 0 | G58: 0 | H58: 0 | I58: 0 | J58: 0 | K58: 0 | L58: 0 | M58: 0 | N58: 0 | O58: 0 | P58: 0 | Q58: 0 | R58: ------- | S58: ------- | T58: ------- | U58: ------- | V58: ------- | W58: ------- | X58: ------- | Y58: ------- | Z58: ------- | AA58: ------- | AB58: ------- | AC58: ------- | AE58: =IF($C58="","",SUM($F58:$Q58)) | AF58: =IF($C58="","",COUNTIF($R58:$AC58,"http*")) | AG58: =IF($C58="","",$AE58*1000+(1000-$A58)) | AH58: =IF($C58="","",RANK($AG58,$AG$2:$AG$60)) | AI58: =IF($C58="","",MAX(0,$AE58-$AF58)) | AJ58: =IF($C58="","",MAX(0,$AF58-$AE58)) | AK58: =IF($C58="","",IF($E58<>$AE58,1,0))
A59: 58 | E59: 1 | F59: 0 | G59: 0 | H59: 0 | I59: 0 | J59: 0 | K59: 0 | L59: 0 | M59: 0 | N59: 0 | O59: 0 | P59: 0 | Q59: 0 | R59: ------- | S59: ------- | T59: ------- | U59: ------- | V59: ------- | W59: ------- | X59: ------- | Y59: ------- | Z59: ------- | AA59: ------- | AB59: ------- | AC59: ------- | AE59: =IF($C59="","",SUM($F59:$Q59)) | AF59: =IF($C59="","",COUNTIF($R59:$AC59,"http*")) | AG59: =IF($C59="","",$AE59*1000+(1000-$A59)) | AH59: =IF($C59="","",RANK($AG59,$AG$2:$AG$60)) | AI59: =IF($C59="","",MAX(0,$AE59-$AF59)) | AJ59: =IF($C59="","",MAX(0,$AF59-$AE59)) | AK59: =IF($C59="","",IF($E59<>$AE59,1,0))
A60: 59 | E60: 1 | F60: 0 | G60: 0 | H60: 0 | I60: 0 | J60: 0 | K60: 0 | L60: 0 | M60: 0 | N60: 0 | O60: 0 | P60: 0 | Q60: 0 | R60: ------- | S60: ------- | T60: ------- | U60: ------- | V60: ------- | W60: ------- | X60: ------- | Y60: ------- | Z60: ------- | AA60: ------- | AB60: ------- | AC60: ------- | AE60: =IF($C60="","",SUM($F60:$Q60)) | AF60: =IF($C60="","",COUNTIF($R60:$AC60,"http*")) | AG60: =IF($C60="","",$AE60*1000+(1000-$A60)) | AH60: =IF($C60="","",RANK($AG60,$AG$2:$AG$60)) | AI60: =IF($C60="","",MAX(0,$AE60-$AF60)) | AJ60: =IF($C60="","",MAX(0,$AF60-$AE60)) | AK60: =IF($C60="","",IF($E60<>$AE60,1,0))

Sheet Periódicos
A1: Nome do periódico | B1: Sigla | C1: Publisher | D1: Impact Factor | E1: Área | F1: Escopo | G1: URL | H1: Exemplo de artigo | I1: Fit com projetos (1–5) | J1: APC | K1: Open Access | L1: Tempo editorial | M1: Observações | N1: Fonte / referência
A2: International Journal of Data Science and Analytics | B2: JDSA | C2: Springer | D2: 2.9 | E2: data science | F2: Data Science has been established as an important emergent scientific field and paradigm driving research evolution in such disciplines as statistics, computing science and intelligence science, and practical transformation in such domains as science, engineering, the public sector, business, social sci­ence, and lifestyle. The field encompasses the larger ar­eas of artificial intelligence, data analytics, machine learning, pattern recognition, natural language understanding, and big data manipulation. It also tackles related new sci­entific chal­lenges, ranging from data capture, creation, storage, retrieval, sharing, analysis, optimization, and vis­ualization, to integrative analysis across heterogeneous and interdependent complex resources for better decision-making, collaboration, and, ultimately, value creation. The International Journal of Data Science and Analytics (JDSA) brings together thought leaders, researchers, industry practitioners, and potential users of data science and analytics, to develop the field, discuss new trends and opportunities, exchange ideas and practices, and promote transdisciplinary and cross-domain collaborations. The jour­nal is composed of three streams: Regular, to communicate original and reproducible theoretical and experimental findings on data science and analytics; Applications, to report the significant data science applications to real-life situations; and Trends, to report expert opinion and comprehensive surveys and reviews of relevant areas and topics in data science and analytics. Topics of relevance include all aspects of the trends, scientific foundations, techniques, and applica­tions of data science and analytics, with a primary focus on: statistical and mathematical foundations for data science and analytics; understanding and analytics of complex data, human, domain, network, organizational, social, behavior, and system characteristics, complexities and intelligences; creation and extraction, processing, representation and modelling, learning and discovery, fusion and integration, presentation and visualization of complex data, behavior, knowledge and intelligence; data analytics, pattern recognition, knowledge discovery, machine learning, deep analytics and deep learning, and intelligent processing of various data (including transaction, text, image, video, graph and network), behaviors and systems; active, real-time, personalized, actionable and automated analytics, learning, computation, optimization, presentation and recommendation; big data architecture, infrastructure, computing, matching, indexing, query processing, mapping, search, retrieval, interopera­bility, exchange, and recommendation; in-memory, distributed, parallel, scalable and high-performance computing, analytics and optimization for big data; review, surveys, trends, prospects and opportunities of data science research, innovation and applications; data science applications, intelligent devices and services in scientific, business, governmental, cultural, behavioral, social and economic, health and medical, human, natural and artificial (including online/Web, cloud, IoT, mobile and social media) domains; and ethics, quality, privacy, safety and security, trust, and risk of data science and analytics | G2: https://link.springer.com/journal/41060 | H2: https://doi.org/10.1007/s41060-023-00454-0 | I2: 5 | J2: Consultar política atual | K2: Híbrido/consultar | L2: 18 dias (mediana até 1ª decisão) | M2: APC deve ser conferido antes da submissão. | N2: https://link.springer.com/journal/41060
A3: Advances in Theoretical and Mathematical Physics | B3: ATMP | C3: International Press | D3: 1 | E3: física | F3: Pesquisa original em física teórica e matemática, especialmente em temas na interface entre física e matemática. | G3: https://intlpress.com/site/pub/pages/journals/items/atmp/_home/_main/index.html | H3: N/D | I3: 5 | J3: Consultar política atual | K3: Não confirmado | L3: Não informado | M3: APC deve ser conferido antes da submissão. Tempo editorial não informado de forma verificável. | N3: https://intlpress.com/site/pub/pages/journals/items/atmp/_home/_main/index.html
A4: Brazilian Journal of Physics | B4: BJP | C4: Springer Nature | D4: 1.7 | E4: física | F4: Pesquisa experimental, teórica e computacional em física, incluindo física atômica, matéria condensada, nuclear, óptica, partículas, física estatística, sistemas complexos e áreas correlatas. | G4: https://www.springer.com/journal/13538 | H4: N/D | I4: 4 | J4: Consultar política atual | K4: Híbrido/consultar | L4: Não informado | M4: APC deve ser conferido antes da submissão. Tempo editorial não informado de forma verificável. | N4: https://www.springer.com/journal/13538
A5: Canadian Journal of Physics | B5: Can. J. Phys. | C5: Canadian Science Publishing | D5: 1.1 | E5: física | F5: Pesquisa ampla em física, incluindo física atômica e molecular, matéria condensada, partículas, nuclear, fluidos e plasmas, óptica, física matemática, relatividade, cosmologia e gravitação. | G5: https://cdnsciencepub.com/journal/cjp | H5: N/D | I5: 4 | J5: Consultar política atual | K5: Não confirmado | L5: Não informado | M5: APC deve ser conferido antes da submissão. Tempo editorial não informado de forma verificável. | N5: https://cdnsciencepub.com/journal/cjp
A6: Chinese Journal of Physics | B6: Chin. J. Phys. | C6: Elsevier | D6: 4.6 | E6: física | F6: The Chinese Journal of Physics publishes important advances in various branches in physics, including: Gravitation and Astrophysics, General Physics. Statistical and Quantum Mechanics, etc. Quantum Information and Quantum Computation | G6: https://www.journals.elsevier.com/chinese-journal-of-physics | H6: N/D | I6: 5 | J6: Consultar política atual | K6: Híbrido/consultar | L6: Não informado | M6: APC deve ser conferido antes da submissão. Tempo editorial não informado de forma verificável. | N6: https://www.journals.elsevier.com/chinese-journal-of-physics
A7: Classical and Quantum Gravity | B7: CQG | C7: IOP Publishing | D7: 3.7 | E7: física | F7: Classical and Quantum Gravity is an established journal for physicists, mathematicians and cosmologists in the fields of gravitation and the theory of spacetime. The journal is now the acknowledged world leader in classical relativity and all areas of quantum gravity. | G7: https://iopscience.iop.org/journal/0264-9381 | H7: https://iopscience.iop.org/article/10.1088/0264-9381/11/5/001 | I7: 5 | J7: Consultar política atual | K7: Híbrido/consultar | L7: Não informado | M7: APC deve ser conferido antes da submissão. Tempo editorial não informado de forma verificável. | N7: https://iopscience.iop.org/journal/0264-9381
A8: Communications in Mathematical Physics | B8: CMP | C8: Springer Nature | D8: 2.9 | E8: física | F8: Pesquisa em física matemática com forte conteúdo matemático e motivação em problemas fundamentais da física moderna. | G8: https://www.springer.com/journal/220 | H8: N/D | I8: 5 | J8: OA: US$ 3.190 / £2.190 / €2.590 | K8: Híbrido | L8: 18 dias (mediana até 1ª decisão) | M8: Dados editoriais sujeitos a atualização; confirmar no site do periódico antes da submissão. | N8: https://www.springer.com/journal/220
A9: Gravitation and Cosmology | B9: Grav. Cosmol. | C9: Springer Nature | D9: 1 | E9: física | F9: Gravitação, cosmologia relativística, astrofísica relativística, soluções exatas, métodos matemáticos e fundamentos de teorias gravitacionais. | G9: https://www.springer.com/journal/10714 | H9: N/D | I9: 5 | J9: Consultar política atual | K9: Híbrido | L9: Não informado | M9: APC deve ser conferido antes da submissão. Tempo editorial não informado de forma verificável. | N9: https://www.springer.com/journal/10714
A10: International Journal of Modern Physics A | B10: IJMPA | C10: World Scientific | D10: 1.2 | E10: física | F10: Física de partículas, teoria quântica de campos, gravitação, cosmologia, física nuclear e temas relacionados de física moderna. | G10: https://www.worldscientific.com/worldscinet/ijmpa | H10: N/D | I10: 5 | J10: Consultar política atual | K10: Híbrido/consultar | L10: Não informado | M10: APC deve ser conferido antes da submissão. Tempo editorial não informado de forma verificável. | N10: https://www.worldscientific.com/worldscinet/ijmpa
A11: International Journal of Theoretical Physics | B11: IJTP | C11: Springer Nature | D11: 1.7 | E11: física | F11: Pesquisa em física teórica, fundamentos quânticos, gravitação, cosmologia, teoria de campos, física matemática e áreas correlatas. | G11: https://www.springer.com/journal/10773 | H11: N/D | I11: 5 | J11: Consultar política atual | K11: Híbrido/consultar | L11: Não informado | M11: APC deve ser conferido antes da submissão. Tempo editorial não informado de forma verificável. | N11: https://www.springer.com/journal/10773
A12: Journal of Computational Physics | B12: JCP | C12: Science Direct | D12: 3.8 | E12: física | F12: The Journal of Computational Physics (JCP) focuses on the computational aspects of physical problems. JCP encourages original scientific contributions in advanced mathematical and numerical modeling reflecting a combination of concepts, methods and principles which are often interdisciplinary in nature and span several areas of physics, mechanics, applied mathematics, statistics, applied geometry, computer science, chemistry and other scientific disciplines as well: the Journal's editors seek to emphasize methods that cross disciplinary boundaries. | G12: https://www.sciencedirect.com/journal/journal-of-computational-physics | H12: N/D | I12: 4 | J12: Consultar política atual | K12: Não confirmado | L12: Não informado | M12: APC deve ser conferido antes da submissão. Tempo editorial não informado de forma verificável. | N12: https://www.sciencedirect.com/journal/journal-of-computational-physics
A13: Journal of High Energy Physics | B13: JHEP | C13: Springer Nature | D13: 5.5 | E13: física | F13: The aim of the Journal of High Energy Physics (JHEP) is to ensure fast and efficient online publication tools to the scientific community, while keeping that community in charge of every aspect of the peer-review and publication process in order to ensure the highest quality standards in the journal. | G13: https://link.springer.com/journal/13130 | H13: N/D | I13: 5 | J13: Consultar política atual | K13: Open Access / SCOAP3 | L13: Não informado | M13: APC deve ser conferido antes da submissão. Tempo editorial não informado de forma verificável. | N13: https://link.springer.com/journal/13130
... A28: Theoretical and Mathematical Physics | B28: TMP | C28: Springer Nature | D28: 1.1 | E28: física | F28: Pesquisa em física teórica e matemática, incluindo teoria quântica de campos, sistemas integráveis, gravitação, cosmologia e métodos matemáticos. | G28: https://www.springer.com/journal/11232 | H28: N/D | I28: 5 | J28: Consultar política atual | K28: Híbrido/consultar | L28: Não informado | M28: APC deve ser conferido antes da submissão. Tempo editorial não informado de forma verificável. | N28: https://www.springer.com/journal/11232
A29: Action in Teacher Education | B29: ATE | C29: Association of Teacher Educators(ATE) | D29: N/D | E29: matemática | F29: Designed for a general teacher ed audience, but it does publish mathematics-specific articles. Particularly interested in action research articles. | G29: https://ate1.org/ate-publications | H29: N/D | I29: 3 | J29: Consultar política atual | K29: Membros/assinatura | L29: 3–4 meses | M29: APC deve ser conferido antes da submissão. | N29: https://docs.google.com/spreadsheets/d/1wSi_RMs07HmPMkirnmFInYvAovt0vWFP9lLaMk694Cc/htmlview/sheet?gid=0&headers=true
A30: AERA Open | B30: AERA Open | C30: American Educational Research Association (AERA) | D30: 2.8 | E30: matemática | F30: "AERA Open is a peer-reviewed, open access journal published by the American Educational Research Association (AERA). With an emphasis on rapid review and dissemination, AERA Open aims to advance knowledge through theoretical and empirical study across arenas of inquiry related to education and learning. AERA Open emphasizes publishing scientific and scholarly work that adds to knowledge incrementally and cumulatively. AERA Open also serves as a venue for innovation, novel inquiry and ideas, interdisciplinary bridge building, and research that fosters the connection of research to practice and practice to research." | G30: https://www.google.com/search?q=%22AERA+Open%22+official+journal | H30: N/D | I30: 3 | J30: Consultar política atual | K30: Open Access | L30: 4–6 meses | M30: Homepage oficial não foi confirmada; a URL fornecida é uma busca de localização. APC deve ser conferido antes da submissão. | N30: https://docs.google.com/spreadsheets/d/1wSi_RMs07HmPMkirnmFInYvAovt0vWFP9lLaMk694Cc/htmlview/sheet?gid=0&headers=true
A31: African Journal of Research in Science, Mathematics and Technology Education | B31: AJRSMTE | C31: Taylor & Francis | D31: 0.5 | E31: matemática | F31: "African Journal of Research in Mathematics, Science and Technology Education (AJRMSTE) is to disseminate, as widely as possible, high quality research findings and well written articles on Curriculum Studies; Teacher Education; Education for Development; Mathematics Education; Science Education; Design & Technology Education and Computer Education. Articles that promote the understanding of curricular policy and diverse socio-cultural issues and those which stimulate epistemological and methodological debates are welcome. The editorial board welcomes articles that will contribute to the overall development of science, mathematics, technology and environmental education in Africa. The focus being the development of research capacity in Africa, AJRMSTE assists first time authors in achieving the high standards to which the journal is committed. Naturally, the journal welcomes contributions from more experienced authors as well." | G31: https://www.google.com/search?q=%22African+Journal+of+Research+in+Science%2C+Mathematics+and+Technology+Education%22+official+journal | H31: N/D | I31: 4 | J31: Consultar política atual | K31: Híbrido | L31: 3–4 meses | M31: Homepage oficial não foi confirmada; a URL fornecida é uma busca de localização. APC deve ser conferido antes da submissão. | N31: https://docs.google.com/spreadsheets/d/1wSi_RMs07HmPMkirnmFInYvAovt0vWFP9lLaMk694Cc/htmlview/sheet?gid=0&headers=true
